<?xml version="1.0" encoding="utf-8"?><testsuites name="pytest tests"><testsuite name="pytest" errors="0" failures="1" skipped="0" tests="6" time="4.623" timestamp="2025-09-20T13:12:32.441973-05:00" hostname="minsky-core"><testcase classname="tests.unit.auth.test_auth_service_tdd.TestAuthServiceUserRegistration" name="test_red_phase_register_user_with_valid_data" time="0.610" /><testcase classname="tests.unit.auth.test_auth_service_tdd.TestAuthServiceUserRegistration" name="test_red_phase_register_user_duplicate_email" time="0.262" /><testcase classname="tests.unit.auth.test_auth_service_tdd.TestAuthServiceUserRegistration" name="test_red_phase_register_user_invalid_email" time="0.024" /><testcase classname="tests.unit.auth.test_auth_service_tdd.TestAuthServiceUserRegistration" name="test_green_phase_password_hashing" time="0.260" /><testcase classname="tests.unit.auth.test_auth_service_tdd.TestAuthServiceUserRegistration" name="test_refactor_phase_user_registration_validation" time="0.034" /><testcase classname="tests.unit.auth.test_auth_service_tdd.TestAuthServiceUserAuthentication" name="test_red_phase_authenticate_valid_credentials" time="0.267"><failure message="AttributeError: &lt;module 'app.services.auth_service' from '/home/admin-jairo/MeStore/app/services/auth_service.py'&gt; does not have the attribute 'verify_password'">tests/unit/auth/test_auth_service_tdd.py:220: in test_red_phase_authenticate_valid_credentials
    with patch('app.services.auth_service.verify_password') as mock_verify:
../.pyenv/versions/3.11.5/lib/python3.11/unittest/mock.py:1443: in __enter__
    original, local = self.get_original()
                      ^^^^^^^^^^^^^^^^^^^
../.pyenv/versions/3.11.5/lib/python3.11/unittest/mock.py:1416: in get_original
    raise AttributeError(
E   AttributeError: &lt;module 'app.services.auth_service' from '/home/admin-jairo/MeStore/app/services/auth_service.py'&gt; does not have the attribute 'verify_password'</failure></testcase></testsuite></testsuites>